<mujoco model="arm">
  <compiler autolimits="true"/>
  <option timestep="0.005" iterations="50" solver="Newton" tolerance="1e-10"/>

  <visual>
    <map force="0.1" zfar="30"/>
    <rgba haze="0.15 0.25 0.35 1"/>
    <global offwidth="2560" offheight="1440" elevation="20" azimuth="120"/>
  </visual>

  <statistic center="0 0 0.7"/>

  <asset>
    <texture type="skybox" builtin="gradient" rgb1=".3 .5 .7" rgb2="0 0 0" width="32" height="512"/>
    <texture name="body" type="cube" builtin="flat" mark="cross" width="128" height="128" rgb1="0.8 0.6 0.4" rgb2="0.8 0.6 0.4" markrgb="1 1 1" random="0.01"/>
    <material name="body" texture="body" texuniform="true" rgba="0.8 0.6 .4 1"/>
    <texture name="grid" type="2d" builtin="checker" width="512" height="512" rgb1=".1 .2 .3" rgb2=".2 .3 .4"/>
    <material name="grid" texture="grid" texrepeat="1 1" texuniform="true" reflectance=".2"/>
  </asset>

  <worldbody>
    <geom name="floor" size="0 0 .05" type="plane" material="grid" condim="3"/>
    
    <light name="spotlight" mode="targetbodycom" target="arm" diffuse=".8 .8 .8" specular="0.3 0.3 0.3" pos="0 -6 4" cutoff="30"/>

    <body name="ball" pos="0 0.5 2">
        <freejoint name="ball"/>
        <geom name="ball" size="0.03" type="sphere" material="body" mass="0.05" group="1" condim="6" friction=".6" solimp=".7 .8 .003" solref=".015 1" />
        <site name="ball"/>
    </body>

    <body name="arm" pos="0 0 0">
      <body name="base" pos="0 0 0.045">
        <geom name="base" type="cylinder" zaxis="0 0 1" size=".08 0.045" rgba=".5 .1 .1 1" condim="6" friction=".6" solimp=".7 .8 .003" solref=".015 1"  mass="0.250"/>
        <joint name="base" type="hinge" solreffriction=".15 1" axis="0 0 1" frictionloss="0.1"/>
        <site name="base"/>

        <body name="shoulder" pos="0 0 0">

          <geom name="upper arm" type="capsule" size="0.045" fromto="0 0 0  0 0 0.5" rgba=".5 .1 .1 1" condim="6" friction=".6" solimp=".7 .8 .003" solref=".015 1"  mass="0.250"/>
          <joint name="shoulder" type="hinge" solreffriction=".15 1" axis="0 1 0" frictionloss="0.1"/>
          <geom name="shoulder" type="cylinder" pos="0 0 0" size=".1 .05" rgba=".5 .1 .8 .5" mass="0.1" group="1" zaxis="0 1 0"/>

          <body name="forearm" pos="0 0 0.5">
            <geom name="forearm" type="capsule" size="0.035" fromto="0 0 0  0 0 0.5" rgba=".5 .1 .1 1" condim="6" friction=".6" solimp=".7 .8 .003" solref=".015 1" mass="0.250"/>
            <joint name="elbow" type="hinge" solreffriction=".15 1" axis="0 1 0" frictionloss="0.1"/>
            <geom name="elbow" type="cylinder" pos="0 0 0" size=".08 .05" rgba=".5 .1 .8 .5" mass="0.1" group="1" zaxis="0 1 0"/>
            <site name="elbow"/>
          </body>

        </body>
      </body>

    </body>

  </worldbody>

  <actuator>
    <position name="base_p" joint="base" ctrlrange="-3.1415 3.1415" kp="120"/>
    <position name="shoulder_p" joint="shoulder" ctrlrange="-3.1415 3.1415" kp="60"/>
    <position name="elbow_p" joint="elbow" ctrlrange="-3.1415 3.1415" kp="10"/>
    <velocity name="shoulder_va" joint="shoulder" ctrlrange="-3.1415 3.1415" kv="0.9"/>
    <velocity name="elbow_va" joint="elbow" ctrlrange="-3.1415 3.1415" kv="0.9"/>
  </actuator>

  <sensor>
    <velocimeter name="ball_vx" site="ball"/>
    <velocimeter name="elbow_vx" site="elbow"/>
  </sensor>

</mujoco>